try{
    callSomeFunc();
    console.log("Конец блока try");
}
catch{
    console.log("Произошла ошибка");
}
finally{
    console.log("Блок finally")
}
 
console.log("Остальные инструкции");

//**Конструкция try также может содержать блок finally. Мы можем использовать этот блок
//  вместе с блоком catch или вместо него. Блок finally выполняется вне зависимости, 
// произошла ошибка или нет.  */